INFO:werkzeug: * Running on http://127.0.0.1:5000/ (Press CTRL+C to quit)
INFO:werkzeug: * Running on http://127.0.0.1:5000/ (Press CTRL+C to quit)
INFO:werkzeug: * Running on http://127.0.0.1:5000/ (Press CTRL+C to quit)
ERROR:flask.app:Exception on /agents [GET]
Traceback (most recent call last):
  File "/usr/local/lib/python3.6/site-packages/flask/app.py", line 2292, in wsgi_app
    response = self.full_dispatch_request()
  File "/usr/local/lib/python3.6/site-packages/flask/app.py", line 1815, in full_dispatch_request
    rv = self.handle_user_exception(e)
  File "/usr/local/lib/python3.6/site-packages/flask/app.py", line 1718, in handle_user_exception
    reraise(exc_type, exc_value, tb)
  File "/usr/local/lib/python3.6/site-packages/flask/_compat.py", line 35, in reraise
    raise value
  File "/usr/local/lib/python3.6/site-packages/flask/app.py", line 1813, in full_dispatch_request
    rv = self.dispatch_request()
  File "/usr/local/lib/python3.6/site-packages/flask/app.py", line 1799, in dispatch_request
    return self.view_functions[rule.endpoint](**req.view_args)
  File "/home/azureuser/python/python-flask-mysql-app/app/views.py", line 19, in agents
    agents = functions.get_agents()
  File "/home/azureuser/python/python-flask-mysql-app/app/functions.py", line 77, in get_agents
    engine = create_engine('mysql://root:Mysql!1221@localhost/test')
  File "<string>", line 2, in create_engine
  File "/usr/local/lib64/python3.6/site-packages/sqlalchemy/util/deprecations.py", line 309, in warned
    return fn(*args, **kwargs)
  File "/usr/local/lib64/python3.6/site-packages/sqlalchemy/engine/create.py", line 560, in create_engine
    dbapi = dialect_cls.dbapi(**dbapi_args)
  File "/usr/local/lib64/python3.6/site-packages/sqlalchemy/dialects/mysql/mysqldb.py", line 163, in dbapi
    return __import__("MySQLdb")
ModuleNotFoundError: No module named 'MySQLdb'
INFO:werkzeug:127.0.0.1 - - [25/Jan/2023 05:40:55] "[35m[1mGET /agents HTTP/1.1[0m" 500 -
INFO:werkzeug:127.0.0.1 - - [25/Jan/2023 05:41:54] "GET / HTTP/1.1" 200 -
ERROR:flask.app:Exception on /agents [GET]
Traceback (most recent call last):
  File "/usr/local/lib/python3.6/site-packages/flask/app.py", line 2292, in wsgi_app
    response = self.full_dispatch_request()
  File "/usr/local/lib/python3.6/site-packages/flask/app.py", line 1815, in full_dispatch_request
    rv = self.handle_user_exception(e)
  File "/usr/local/lib/python3.6/site-packages/flask/app.py", line 1718, in handle_user_exception
    reraise(exc_type, exc_value, tb)
  File "/usr/local/lib/python3.6/site-packages/flask/_compat.py", line 35, in reraise
    raise value
  File "/usr/local/lib/python3.6/site-packages/flask/app.py", line 1813, in full_dispatch_request
    rv = self.dispatch_request()
  File "/usr/local/lib/python3.6/site-packages/flask/app.py", line 1799, in dispatch_request
    return self.view_functions[rule.endpoint](**req.view_args)
  File "/home/azureuser/python/python-flask-mysql-app/app/views.py", line 19, in agents
    agents = functions.get_agents()
  File "/home/azureuser/python/python-flask-mysql-app/app/functions.py", line 77, in get_agents
    engine = create_engine('mysql://root:Mysql!1221@localhost/test')
  File "<string>", line 2, in create_engine
  File "/usr/local/lib64/python3.6/site-packages/sqlalchemy/util/deprecations.py", line 309, in warned
    return fn(*args, **kwargs)
  File "/usr/local/lib64/python3.6/site-packages/sqlalchemy/engine/create.py", line 560, in create_engine
    dbapi = dialect_cls.dbapi(**dbapi_args)
  File "/usr/local/lib64/python3.6/site-packages/sqlalchemy/dialects/mysql/mysqldb.py", line 163, in dbapi
    return __import__("MySQLdb")
ModuleNotFoundError: No module named 'MySQLdb'
INFO:werkzeug:127.0.0.1 - - [25/Jan/2023 05:43:44] "[35m[1mGET /agents HTTP/1.1[0m" 500 -
INFO:werkzeug: * Running on http://127.0.0.1:5000/ (Press CTRL+C to quit)
ERROR:flask.app:Exception on /agents [GET]
Traceback (most recent call last):
  File "/usr/local/lib/python3.6/site-packages/flask/app.py", line 2292, in wsgi_app
    response = self.full_dispatch_request()
  File "/usr/local/lib/python3.6/site-packages/flask/app.py", line 1815, in full_dispatch_request
    rv = self.handle_user_exception(e)
  File "/usr/local/lib/python3.6/site-packages/flask/app.py", line 1718, in handle_user_exception
    reraise(exc_type, exc_value, tb)
  File "/usr/local/lib/python3.6/site-packages/flask/_compat.py", line 35, in reraise
    raise value
  File "/usr/local/lib/python3.6/site-packages/flask/app.py", line 1813, in full_dispatch_request
    rv = self.dispatch_request()
  File "/usr/local/lib/python3.6/site-packages/flask/app.py", line 1799, in dispatch_request
    return self.view_functions[rule.endpoint](**req.view_args)
  File "/home/azureuser/python/python-flask-mysql-app/app/views.py", line 19, in agents
    agents = functions.get_agents()
  File "/home/azureuser/python/python-flask-mysql-app/app/functions.py", line 77, in get_agents
    engine = create_engine('mysql://root:Mysql!1221@localhost/test')
  File "<string>", line 2, in create_engine
  File "/usr/local/lib64/python3.6/site-packages/sqlalchemy/util/deprecations.py", line 309, in warned
    return fn(*args, **kwargs)
  File "/usr/local/lib64/python3.6/site-packages/sqlalchemy/engine/create.py", line 560, in create_engine
    dbapi = dialect_cls.dbapi(**dbapi_args)
  File "/usr/local/lib64/python3.6/site-packages/sqlalchemy/dialects/mysql/mysqldb.py", line 163, in dbapi
    return __import__("MySQLdb")
ModuleNotFoundError: No module named 'MySQLdb'
INFO:werkzeug:127.0.0.1 - - [25/Jan/2023 05:45:40] "[35m[1mGET /agents HTTP/1.1[0m" 500 -
INFO:werkzeug: * Running on http://127.0.0.1:5000/ (Press CTRL+C to quit)
INFO:werkzeug: * Restarting with stat
WARNING:werkzeug: * Debugger is active!
INFO:werkzeug: * Debugger PIN: 137-574-450
INFO:werkzeug:127.0.0.1 - - [25/Jan/2023 05:48:13] "[35m[1mGET /agents HTTP/1.1[0m" 500 -
INFO:werkzeug: * Running on http://127.0.0.1:5000/ (Press CTRL+C to quit)
ERROR:flask.app:Exception on /agents [GET]
Traceback (most recent call last):
  File "/usr/local/lib64/python3.6/site-packages/sqlalchemy/engine/base.py", line 3240, in _wrap_pool_connect
    return fn()
  File "/usr/local/lib64/python3.6/site-packages/sqlalchemy/pool/base.py", line 310, in connect
    return _ConnectionFairy._checkout(self)
  File "/usr/local/lib64/python3.6/site-packages/sqlalchemy/pool/base.py", line 868, in _checkout
    fairy = _ConnectionRecord.checkout(pool)
  File "/usr/local/lib64/python3.6/site-packages/sqlalchemy/pool/base.py", line 476, in checkout
    rec = pool._do_get()
  File "/usr/local/lib64/python3.6/site-packages/sqlalchemy/pool/impl.py", line 146, in _do_get
    self._dec_overflow()
  File "/usr/local/lib64/python3.6/site-packages/sqlalchemy/util/langhelpers.py", line 72, in __exit__
    with_traceback=exc_tb,
  File "/usr/local/lib64/python3.6/site-packages/sqlalchemy/util/compat.py", line 207, in raise_
    raise exception
  File "/usr/local/lib64/python3.6/site-packages/sqlalchemy/pool/impl.py", line 143, in _do_get
    return self._create_connection()
  File "/usr/local/lib64/python3.6/site-packages/sqlalchemy/pool/base.py", line 256, in _create_connection
    return _ConnectionRecord(self)
  File "/usr/local/lib64/python3.6/site-packages/sqlalchemy/pool/base.py", line 371, in __init__
    self.__connect()
  File "/usr/local/lib64/python3.6/site-packages/sqlalchemy/pool/base.py", line 666, in __connect
    pool.logger.debug("Error on connect(): %s", e)
  File "/usr/local/lib64/python3.6/site-packages/sqlalchemy/util/langhelpers.py", line 72, in __exit__
    with_traceback=exc_tb,
  File "/usr/local/lib64/python3.6/site-packages/sqlalchemy/util/compat.py", line 207, in raise_
    raise exception
  File "/usr/local/lib64/python3.6/site-packages/sqlalchemy/pool/base.py", line 661, in __connect
    self.dbapi_connection = connection = pool._invoke_creator(self)
  File "/usr/local/lib64/python3.6/site-packages/sqlalchemy/engine/create.py", line 590, in connect
    return dialect.connect(*cargs, **cparams)
  File "/usr/local/lib64/python3.6/site-packages/sqlalchemy/engine/default.py", line 584, in connect
    return self.dbapi.connect(*cargs, **cparams)
  File "/usr/local/lib64/python3.6/site-packages/MySQLdb/__init__.py", line 130, in Connect
    return Connection(*args, **kwargs)
  File "/usr/local/lib64/python3.6/site-packages/MySQLdb/connections.py", line 185, in __init__
    super().__init__(*args, **kwargs2)
MySQLdb._exceptions.OperationalError: (1045, "Access denied for user 'root'@'localhost' (using password: YES)")

The above exception was the direct cause of the following exception:

Traceback (most recent call last):
  File "/usr/local/lib/python3.6/site-packages/flask/app.py", line 2292, in wsgi_app
    response = self.full_dispatch_request()
  File "/usr/local/lib/python3.6/site-packages/flask/app.py", line 1815, in full_dispatch_request
    rv = self.handle_user_exception(e)
  File "/usr/local/lib/python3.6/site-packages/flask/app.py", line 1718, in handle_user_exception
    reraise(exc_type, exc_value, tb)
  File "/usr/local/lib/python3.6/site-packages/flask/_compat.py", line 35, in reraise
    raise value
  File "/usr/local/lib/python3.6/site-packages/flask/app.py", line 1813, in full_dispatch_request
    rv = self.dispatch_request()
  File "/usr/local/lib/python3.6/site-packages/flask/app.py", line 1799, in dispatch_request
    return self.view_functions[rule.endpoint](**req.view_args)
  File "/home/azureuser/python/python-flask-mysql-app/app/views.py", line 19, in agents
    agents = functions.get_agents()
  File "/home/azureuser/python/python-flask-mysql-app/app/functions.py", line 78, in get_agents
    connection = engine.connect()
  File "/usr/local/lib64/python3.6/site-packages/sqlalchemy/engine/base.py", line 3194, in connect
    return self._connection_cls(self, close_with_result=close_with_result)
  File "/usr/local/lib64/python3.6/site-packages/sqlalchemy/engine/base.py", line 96, in __init__
    else engine.raw_connection()
  File "/usr/local/lib64/python3.6/site-packages/sqlalchemy/engine/base.py", line 3273, in raw_connection
    return self._wrap_pool_connect(self.pool.connect, _connection)
  File "/usr/local/lib64/python3.6/site-packages/sqlalchemy/engine/base.py", line 3244, in _wrap_pool_connect
    e, dialect, self
  File "/usr/local/lib64/python3.6/site-packages/sqlalchemy/engine/base.py", line 2098, in _handle_dbapi_exception_noconnection
    sqlalchemy_exception, with_traceback=exc_info[2], from_=e
  File "/usr/local/lib64/python3.6/site-packages/sqlalchemy/util/compat.py", line 207, in raise_
    raise exception
  File "/usr/local/lib64/python3.6/site-packages/sqlalchemy/engine/base.py", line 3240, in _wrap_pool_connect
    return fn()
  File "/usr/local/lib64/python3.6/site-packages/sqlalchemy/pool/base.py", line 310, in connect
    return _ConnectionFairy._checkout(self)
  File "/usr/local/lib64/python3.6/site-packages/sqlalchemy/pool/base.py", line 868, in _checkout
    fairy = _ConnectionRecord.checkout(pool)
  File "/usr/local/lib64/python3.6/site-packages/sqlalchemy/pool/base.py", line 476, in checkout
    rec = pool._do_get()
  File "/usr/local/lib64/python3.6/site-packages/sqlalchemy/pool/impl.py", line 146, in _do_get
    self._dec_overflow()
  File "/usr/local/lib64/python3.6/site-packages/sqlalchemy/util/langhelpers.py", line 72, in __exit__
    with_traceback=exc_tb,
  File "/usr/local/lib64/python3.6/site-packages/sqlalchemy/util/compat.py", line 207, in raise_
    raise exception
  File "/usr/local/lib64/python3.6/site-packages/sqlalchemy/pool/impl.py", line 143, in _do_get
    return self._create_connection()
  File "/usr/local/lib64/python3.6/site-packages/sqlalchemy/pool/base.py", line 256, in _create_connection
    return _ConnectionRecord(self)
  File "/usr/local/lib64/python3.6/site-packages/sqlalchemy/pool/base.py", line 371, in __init__
    self.__connect()
  File "/usr/local/lib64/python3.6/site-packages/sqlalchemy/pool/base.py", line 666, in __connect
    pool.logger.debug("Error on connect(): %s", e)
  File "/usr/local/lib64/python3.6/site-packages/sqlalchemy/util/langhelpers.py", line 72, in __exit__
    with_traceback=exc_tb,
  File "/usr/local/lib64/python3.6/site-packages/sqlalchemy/util/compat.py", line 207, in raise_
    raise exception
  File "/usr/local/lib64/python3.6/site-packages/sqlalchemy/pool/base.py", line 661, in __connect
    self.dbapi_connection = connection = pool._invoke_creator(self)
  File "/usr/local/lib64/python3.6/site-packages/sqlalchemy/engine/create.py", line 590, in connect
    return dialect.connect(*cargs, **cparams)
  File "/usr/local/lib64/python3.6/site-packages/sqlalchemy/engine/default.py", line 584, in connect
    return self.dbapi.connect(*cargs, **cparams)
  File "/usr/local/lib64/python3.6/site-packages/MySQLdb/__init__.py", line 130, in Connect
    return Connection(*args, **kwargs)
  File "/usr/local/lib64/python3.6/site-packages/MySQLdb/connections.py", line 185, in __init__
    super().__init__(*args, **kwargs2)
sqlalchemy.exc.OperationalError: (MySQLdb._exceptions.OperationalError) (1045, "Access denied for user 'root'@'localhost' (using password: YES)")
(Background on this error at: https://sqlalche.me/e/14/e3q8)
INFO:werkzeug:127.0.0.1 - - [25/Jan/2023 13:02:06] "[35m[1mGET /agents HTTP/1.1[0m" 500 -
INFO:werkzeug: * Running on http://127.0.0.1:5000/ (Press CTRL+C to quit)
INFO:werkzeug: * Restarting with stat
WARNING:werkzeug: * Debugger is active!
INFO:werkzeug: * Debugger PIN: 137-574-450
INFO:werkzeug:127.0.0.1 - - [25/Jan/2023 13:02:28] "[35m[1mGET /agents HTTP/1.1[0m" 500 -
INFO:werkzeug: * Running on http://127.0.0.1:5000/ (Press CTRL+C to quit)
INFO:werkzeug: * Restarting with stat
WARNING:werkzeug: * Debugger is active!
INFO:werkzeug: * Debugger PIN: 137-574-450
INFO:werkzeug:127.0.0.1 - - [25/Jan/2023 13:03:47] "[35m[1mGET /agents HTTP/1.1[0m" 500 -
INFO:werkzeug:127.0.0.1 - - [25/Jan/2023 13:03:58] "[35m[1mGET /companies HTTP/1.1[0m" 500 -
INFO:werkzeug: * Running on http://127.0.0.1:5000/ (Press CTRL+C to quit)
INFO:werkzeug: * Restarting with stat
WARNING:werkzeug: * Debugger is active!
INFO:werkzeug: * Debugger PIN: 137-574-450
INFO:werkzeug:127.0.0.1 - - [25/Jan/2023 13:07:11] "[35m[1mGET /companies HTTP/1.1[0m" 500 -
INFO:werkzeug:127.0.0.1 - - [25/Jan/2023 13:07:15] "[35m[1mGET /agents HTTP/1.1[0m" 500 -
INFO:werkzeug: * Running on http://127.0.0.1:5000/ (Press CTRL+C to quit)
INFO:werkzeug:127.0.0.1 - - [25/Jan/2023 17:59:21] "GET /agents HTTP/1.1" 200 -
INFO:werkzeug: * Running on http://127.0.0.1:5000/ (Press CTRL+C to quit)
INFO:werkzeug:127.0.0.1 - - [25/Jan/2023 18:05:39] "GET /agents HTTP/1.1" 200 -
INFO:werkzeug:127.0.0.1 - - [25/Jan/2023 18:05:41] "GET /agents HTTP/1.1" 200 -
INFO:werkzeug: * Running on http://127.0.0.1:5000/ (Press CTRL+C to quit)
INFO:werkzeug: * Running on http://127.0.0.1:5000/ (Press CTRL+C to quit)
INFO:werkzeug:127.0.0.1 - - [25/Jan/2023 20:08:16] "GET /agents HTTP/1.1" 200 -
INFO:werkzeug:127.0.0.1 - - [25/Jan/2023 20:08:19] "GET /agents HTTP/1.1" 200 -
INFO:werkzeug: * Running on http://127.0.0.1:5000/ (Press CTRL+C to quit)
INFO:werkzeug:127.0.0.1 - - [25/Jan/2023 23:21:25] "GET /agents HTTP/1.1" 200 -
INFO:werkzeug:127.0.0.1 - - [25/Jan/2023 23:21:36] "GET /companies HTTP/1.1" 200 -
INFO:werkzeug: * Running on http://127.0.0.1:5000/ (Press CTRL+C to quit)
INFO:werkzeug:127.0.0.1 - - [25/Jan/2023 23:24:24] "GET /companies HTTP/1.1" 200 -
INFO:werkzeug:127.0.0.1 - - [25/Jan/2023 23:24:27] "GET /agents HTTP/1.1" 200 -
INFO:werkzeug:127.0.0.1 - - [25/Jan/2023 23:24:30] "GET /agents HTTP/1.1" 200 -
INFO:werkzeug: * Running on http://127.0.0.1:5000/ (Press CTRL+C to quit)
INFO:werkzeug: * Restarting with stat
WARNING:werkzeug: * Debugger is active!
INFO:werkzeug: * Debugger PIN: 104-264-923
INFO:werkzeug:127.0.0.1 - - [25/Jan/2023 23:26:04] "GET /agents HTTP/1.1" 200 -
INFO:werkzeug: * Running on http://127.0.0.1:5000/ (Press CTRL+C to quit)
INFO:werkzeug:127.0.0.1 - - [30/Jan/2023 20:16:02] "GET /agents HTTP/1.1" 200 -
INFO:werkzeug: * Running on http://127.0.0.1:5000/ (Press CTRL+C to quit)
INFO:werkzeug:127.0.0.1 - - [31/Jan/2023 04:54:01] "GET /agents HTTP/1.1" 200 -
INFO:werkzeug: * Running on http://127.0.0.1:5000/ (Press CTRL+C to quit)
INFO:werkzeug:127.0.0.1 - - [31/Jan/2023 04:59:24] "GET /agents HTTP/1.1" 200 -
WARNING:opentelemetry.exporter.otlp.proto.grpc.exporter:Transient error StatusCode.UNAVAILABLE encountered while exporting traces, retrying in 1s.
WARNING:opentelemetry.exporter.otlp.proto.grpc.exporter:Transient error StatusCode.UNAVAILABLE encountered while exporting traces, retrying in 2s.
WARNING:opentelemetry.exporter.otlp.proto.grpc.exporter:Transient error StatusCode.UNAVAILABLE encountered while exporting traces, retrying in 4s.
WARNING:opentelemetry.exporter.otlp.proto.grpc.exporter:Transient error StatusCode.UNAVAILABLE encountered while exporting traces, retrying in 8s.
WARNING:opentelemetry.exporter.otlp.proto.grpc.exporter:Transient error StatusCode.UNAVAILABLE encountered while exporting traces, retrying in 16s.
ERROR:opentelemetry.exporter.otlp.proto.grpc.exporter:Failed to export metrics, error code: StatusCode.UNIMPLEMENTED
INFO:werkzeug: * Running on http://127.0.0.1:5000/ (Press CTRL+C to quit)
INFO:werkzeug: * Restarting with stat
WARNING:werkzeug: * Debugger is active!
INFO:werkzeug: * Debugger PIN: 906-180-464
INFO:werkzeug:127.0.0.1 - - [31/Jan/2023 05:00:30] "GET /agents HTTP/1.1" 200 -
ERROR:opentelemetry.exporter.otlp.proto.grpc.exporter:Failed to export metrics, error code: StatusCode.UNIMPLEMENTED
ERROR:opentelemetry.exporter.otlp.proto.grpc.exporter:Failed to export metrics, error code: StatusCode.UNIMPLEMENTED
ERROR:opentelemetry.exporter.otlp.proto.grpc.exporter:Failed to export metrics, error code: StatusCode.UNIMPLEMENTED
ERROR:opentelemetry.exporter.otlp.proto.grpc.exporter:Failed to export metrics, error code: StatusCode.UNIMPLEMENTED
ERROR:opentelemetry.exporter.otlp.proto.grpc.exporter:Failed to export metrics, error code: StatusCode.UNIMPLEMENTED
ERROR:opentelemetry.exporter.otlp.proto.grpc.exporter:Failed to export metrics, error code: StatusCode.UNIMPLEMENTED
ERROR:opentelemetry.exporter.otlp.proto.grpc.exporter:Failed to export metrics, error code: StatusCode.UNIMPLEMENTED
ERROR:opentelemetry.exporter.otlp.proto.grpc.exporter:Failed to export metrics, error code: StatusCode.UNIMPLEMENTED
ERROR:opentelemetry.exporter.otlp.proto.grpc.exporter:Failed to export metrics, error code: StatusCode.UNIMPLEMENTED
ERROR:opentelemetry.exporter.otlp.proto.grpc.exporter:Failed to export metrics, error code: StatusCode.UNIMPLEMENTED
ERROR:opentelemetry.exporter.otlp.proto.grpc.exporter:Failed to export metrics, error code: StatusCode.UNIMPLEMENTED
ERROR:opentelemetry.exporter.otlp.proto.grpc.exporter:Failed to export metrics, error code: StatusCode.UNIMPLEMENTED
ERROR:opentelemetry.exporter.otlp.proto.grpc.exporter:Failed to export metrics, error code: StatusCode.UNIMPLEMENTED
INFO:werkzeug: * Running on http://127.0.0.1:5000/ (Press CTRL+C to quit)
INFO:werkzeug:127.0.0.1 - - [31/Jan/2023 05:28:55] "GET /agents HTTP/1.1" 200 -
DEBUG:urllib3.connectionpool:Starting new HTTP connection (1): localhost:4318
DEBUG:urllib3.connectionpool:http://localhost:4318 "POST /v1/traces HTTP/1.1" 200 0
INFO:werkzeug: * Running on http://127.0.0.1:5000/ (Press CTRL+C to quit)
INFO:werkzeug:127.0.0.1 - - [31/Jan/2023 05:40:36] "GET /agents HTTP/1.1" 200 -
DEBUG:urllib3.connectionpool:Starting new HTTP connection (1): localhost:4318
DEBUG:urllib3.connectionpool:http://localhost:4318 "POST /v1/traces HTTP/1.1" 200 0
INFO:werkzeug: * Running on http://127.0.0.1:5000/ (Press CTRL+C to quit)
INFO:werkzeug:127.0.0.1 - - [31/Jan/2023 05:46:16] "GET /agents HTTP/1.1" 200 -
DEBUG:urllib3.connectionpool:Starting new HTTP connection (1): localhost:4318
DEBUG:urllib3.connectionpool:http://localhost:4318 "POST /v1/traces HTTP/1.1" 200 0
INFO:werkzeug: * Running on http://127.0.0.1:5000/ (Press CTRL+C to quit)
INFO:werkzeug:127.0.0.1 - - [31/Jan/2023 16:38:55] "GET /agents HTTP/1.1" 200 -
DEBUG:urllib3.connectionpool:Starting new HTTP connection (1): localhost:4318
DEBUG:urllib3.connectionpool:http://localhost:4318 "POST /v1/traces HTTP/1.1" 200 0
INFO:werkzeug: * Running on http://127.0.0.1:5000/ (Press CTRL+C to quit)
INFO:werkzeug: * Running on http://127.0.0.1:5000/ (Press CTRL+C to quit)
INFO:werkzeug: * Running on http://127.0.0.1:5000/ (Press CTRL+C to quit)
INFO:werkzeug:127.0.0.1 - - [01/Feb/2023 14:34:52] "GET /agents HTTP/1.1" 200 -
DEBUG:urllib3.connectionpool:Starting new HTTP connection (1): localhost:4318
DEBUG:urllib3.connectionpool:http://localhost:4318 "POST /v1/traces HTTP/1.1" 200 0
INFO:werkzeug: * Running on http://127.0.0.1:5000/ (Press CTRL+C to quit)
ERROR:flask.app:Exception on /agents [GET]
Traceback (most recent call last):
  File "/usr/local/lib/python3.9/site-packages/flask/app.py", line 2292, in wsgi_app
    response = self.full_dispatch_request()
  File "/usr/local/lib/python3.9/site-packages/flask/app.py", line 1815, in full_dispatch_request
    rv = self.handle_user_exception(e)
  File "/usr/local/lib/python3.9/site-packages/flask/app.py", line 1718, in handle_user_exception
    reraise(exc_type, exc_value, tb)
  File "/usr/local/lib/python3.9/site-packages/flask/_compat.py", line 35, in reraise
    raise value
  File "/usr/local/lib/python3.9/site-packages/flask/app.py", line 1813, in full_dispatch_request
    rv = self.dispatch_request()
  File "/usr/local/lib/python3.9/site-packages/flask/app.py", line 1799, in dispatch_request
    return self.view_functions[rule.endpoint](**req.view_args)
  File "/home/azureuser/python/python-flask-mysql-app/app/views.py", line 19, in agents
    agents = functions.get_agents()
  File "/home/azureuser/python/python-flask-mysql-app/app/functions.py", line 104, in get_agents
    engine = sqlalchemy.create_engine('mysql://root:Mysql!1221@localhost/flaskapp')
NameError: name 'sqlalchemy' is not defined
INFO:werkzeug:127.0.0.1 - - [01/Feb/2023 14:44:20] "[35m[1mGET /agents HTTP/1.1[0m" 500 -
DEBUG:urllib3.connectionpool:Starting new HTTP connection (1): localhost:4318
DEBUG:urllib3.connectionpool:http://localhost:4318 "POST /v1/traces HTTP/1.1" 200 0
INFO:werkzeug: * Running on http://127.0.0.1:5000/ (Press CTRL+C to quit)
INFO:werkzeug: * Restarting with stat
WARNING:werkzeug: * Debugger is active!
INFO:werkzeug: * Debugger PIN: 906-180-464
INFO:werkzeug:127.0.0.1 - - [01/Feb/2023 14:46:47] "[35m[1mGET /agents HTTP/1.1[0m" 500 -
INFO:werkzeug: * Running on http://127.0.0.1:5000/ (Press CTRL+C to quit)
ERROR:flask.app:Exception on /agents [GET]
Traceback (most recent call last):
  File "/usr/local/lib/python3.9/site-packages/flask/app.py", line 2292, in wsgi_app
    response = self.full_dispatch_request()
  File "/usr/local/lib/python3.9/site-packages/flask/app.py", line 1815, in full_dispatch_request
    rv = self.handle_user_exception(e)
  File "/usr/local/lib/python3.9/site-packages/flask/app.py", line 1718, in handle_user_exception
    reraise(exc_type, exc_value, tb)
  File "/usr/local/lib/python3.9/site-packages/flask/_compat.py", line 35, in reraise
    raise value
  File "/usr/local/lib/python3.9/site-packages/flask/app.py", line 1813, in full_dispatch_request
    rv = self.dispatch_request()
  File "/usr/local/lib/python3.9/site-packages/flask/app.py", line 1799, in dispatch_request
    return self.view_functions[rule.endpoint](**req.view_args)
  File "/home/azureuser/python/python-flask-mysql-app/app/views.py", line 19, in agents
    agents = functions.get_agents()
  File "/home/azureuser/python/python-flask-mysql-app/app/functions.py", line 104, in get_agents
    engine = sqlalchemy.create_engine('mysql://root:Mysql!1221@localhost/flaskapp')
NameError: name 'sqlalchemy' is not defined
INFO:werkzeug:127.0.0.1 - - [02/Feb/2023 04:55:58] "[35m[1mGET /agents HTTP/1.1[0m" 500 -
DEBUG:urllib3.connectionpool:Starting new HTTP connection (1): localhost:4318
DEBUG:urllib3.connectionpool:http://localhost:4318 "POST /v1/traces HTTP/1.1" 200 0
INFO:werkzeug: * Running on http://127.0.0.1:5000/ (Press CTRL+C to quit)
INFO:werkzeug: * Restarting with stat
WARNING:werkzeug: * Debugger is active!
INFO:werkzeug: * Debugger PIN: 906-180-464
INFO:werkzeug:127.0.0.1 - - [02/Feb/2023 04:57:10] "[35m[1mGET /agents HTTP/1.1[0m" 500 -
INFO:werkzeug: * Running on http://127.0.0.1:5000/ (Press CTRL+C to quit)
INFO:werkzeug: * Restarting with stat
WARNING:werkzeug: * Debugger is active!
INFO:werkzeug: * Debugger PIN: 906-180-464
INFO:werkzeug:127.0.0.1 - - [02/Feb/2023 04:58:54] "[35m[1mGET /agents HTTP/1.1[0m" 500 -
INFO:werkzeug: * Running on http://127.0.0.1:5000/ (Press CTRL+C to quit)
INFO:werkzeug: * Restarting with stat
WARNING:werkzeug: * Debugger is active!
INFO:werkzeug: * Debugger PIN: 906-180-464
INFO:werkzeug:127.0.0.1 - - [02/Feb/2023 05:02:26] "GET /agents HTTP/1.1" 200 -
DEBUG:urllib3.connectionpool:Starting new HTTP connection (1): localhost:4318
DEBUG:urllib3.connectionpool:http://localhost:4318 "POST /v1/traces HTTP/1.1" 200 0
INFO:werkzeug:127.0.0.1 - - [02/Feb/2023 05:02:35] "GET /agents HTTP/1.1" 200 -
DEBUG:urllib3.connectionpool:http://localhost:4318 "POST /v1/traces HTTP/1.1" 200 0
INFO:werkzeug: * Running on http://127.0.0.1:5000/ (Press CTRL+C to quit)
INFO:werkzeug:127.0.0.1 - - [14/Feb/2023 17:31:37] "GET / HTTP/1.1" 200 -
DEBUG:urllib3.connectionpool:Starting new HTTP connection (1): localhost:4318
DEBUG:urllib3.connectionpool:http://localhost:4318 "POST /v1/traces HTTP/1.1" 200 0
DEBUG:urllib3.connectionpool:http://localhost:4318 "POST /v1/traces HTTP/1.1" 200 0
INFO:werkzeug:127.0.0.1 - - [14/Feb/2023 17:31:44] "GET /agents HTTP/1.1" 200 -
DEBUG:urllib3.connectionpool:http://localhost:4318 "POST /v1/traces HTTP/1.1" 200 0
INFO:werkzeug:127.0.0.1 - - [14/Feb/2023 17:32:06] "GET /companies HTTP/1.1" 200 -
DEBUG:urllib3.connectionpool:http://localhost:4318 "POST /v1/traces HTTP/1.1" 200 0
INFO:werkzeug: * Running on http://127.0.0.1:5000/ (Press CTRL+C to quit)
INFO:werkzeug:127.0.0.1 - - [14/Feb/2023 17:37:21] "GET /companies HTTP/1.1" 200 -
INFO:werkzeug:127.0.0.1 - - [14/Feb/2023 17:37:24] "GET /companies HTTP/1.1" 200 -
INFO:werkzeug:127.0.0.1 - - [14/Feb/2023 17:37:27] "GET /companies HTTP/1.1" 200 -
INFO:werkzeug: * Running on http://127.0.0.1:5000/ (Press CTRL+C to quit)
INFO:werkzeug:127.0.0.1 - - [14/Feb/2023 17:50:37] "GET /companies HTTP/1.1" 200 -
INFO:werkzeug:127.0.0.1 - - [14/Feb/2023 17:50:39] "GET /companies HTTP/1.1" 200 -
INFO:werkzeug:127.0.0.1 - - [14/Feb/2023 17:50:41] "GET /companies HTTP/1.1" 200 -
INFO:werkzeug: * Running on http://127.0.0.1:5000/ (Press CTRL+C to quit)
INFO:werkzeug:127.0.0.1 - - [14/Feb/2023 17:51:14] "GET /companies HTTP/1.1" 200 -
DEBUG:urllib3.connectionpool:Starting new HTTP connection (1): localhost:4318
DEBUG:urllib3.connectionpool:http://localhost:4318 "POST /v1/traces HTTP/1.1" 200 0
INFO:werkzeug:127.0.0.1 - - [14/Feb/2023 17:51:16] "GET /companies HTTP/1.1" 200 -
INFO:werkzeug:127.0.0.1 - - [14/Feb/2023 17:51:17] "GET /companies HTTP/1.1" 200 -
DEBUG:urllib3.connectionpool:http://localhost:4318 "POST /v1/traces HTTP/1.1" 200 0
INFO:werkzeug: * Running on http://127.0.0.1:5000/ (Press CTRL+C to quit)
INFO:werkzeug:127.0.0.1 - - [19/Feb/2023 01:28:15] "GET /companies HTTP/1.1" 200 -
DEBUG:urllib3.connectionpool:Starting new HTTP connection (1): localhost:4318
DEBUG:urllib3.connectionpool:http://localhost:4318 "POST /v1/traces HTTP/1.1" 200 0
INFO:werkzeug: * Running on http://127.0.0.1:5000/ (Press CTRL+C to quit)
INFO:werkzeug:127.0.0.1 - - [19/Feb/2023 02:40:36] "GET /companies HTTP/1.1" 200 -
DEBUG:urllib3.connectionpool:Starting new HTTP connection (1): localhost:4318
DEBUG:urllib3.connectionpool:http://localhost:4318 "POST /v1/traces HTTP/1.1" 200 0
